<?xml version="1.0" encoding="UTF-8"?>
<!-- Generated by org.testng.reporters.JUnitReportReporter -->
<testsuite hostname="DESKTOP-OOA8I55" failures="0" tests="1" name="Salesforce.E2E_AutomationTest.ValidateTitle" time="4.656" errors="1" timestamp="30 Jun 2021 18:57:49 GMT">
  <testcase classname="Salesforce.E2E_AutomationTest.ValidateTitle" name="validateTitle" time="4.656">
    <error message="expected [Get back to growth with the world’s #1 CRM, powered by Customer 360] but found [Get back to growth with the world’s #1 CRM, powered by Customer 360.]" type="java.lang.AssertionError">
      <![CDATA[java.lang.AssertionError: expected [Get back to growth with the world’s #1 CRM, powered by Customer 360] but found [Get back to growth with the world’s #1 CRM, powered by Customer 360.]
	at org.testng.Assert.fail(Assert.java:94)
	at org.testng.Assert.failNotEquals(Assert.java:494)
	at org.testng.Assert.assertEquals(Assert.java:123)
	at org.testng.Assert.assertEquals(Assert.java:176)
	at org.testng.Assert.assertEquals(Assert.java:186)
	at Salesforce.E2E_AutomationTest.ValidateTitle.validateTitle(ValidateTitle.java:45)
	at java.base/jdk.internal.reflect.NativeMethodAccessorImpl.invoke0(Native Method)
	at java.base/jdk.internal.reflect.NativeMethodAccessorImpl.invoke(NativeMethodAccessorImpl.java:64)
	at java.base/jdk.internal.reflect.DelegatingMethodAccessorImpl.invoke(DelegatingMethodAccessorImpl.java:43)
	at java.base/java.lang.reflect.Method.invoke(Method.java:564)
	at org.testng.internal.MethodInvocationHelper.invokeMethod(MethodInvocationHelper.java:80)
	at org.testng.internal.Invoker.invokeMethod(Invoker.java:714)
	at org.testng.internal.Invoker.invokeTestMethod(Invoker.java:901)
	at org.testng.internal.Invoker.invokeTestMethods(Invoker.java:1231)
	at org.testng.internal.TestMethodWorker.invokeTestMethods(TestMethodWorker.java:127)
	at org.testng.internal.TestMethodWorker.run(TestMethodWorker.java:111)
	at org.testng.TestRunner.privateRun(TestRunner.java:767)
	at org.testng.TestRunner.run(TestRunner.java:617)
	at org.testng.SuiteRunner.runTest(SuiteRunner.java:334)
	at org.testng.SuiteRunner.access$000(SuiteRunner.java:37)
	at org.testng.SuiteRunner$SuiteWorker.run(SuiteRunner.java:368)
	at org.testng.internal.thread.ThreadUtil$2.call(ThreadUtil.java:64)
	at java.base/java.util.concurrent.FutureTask.run(FutureTask.java:264)
	at java.base/java.util.concurrent.ThreadPoolExecutor.runWorker(ThreadPoolExecutor.java:1130)
	at java.base/java.util.concurrent.ThreadPoolExecutor$Worker.run(ThreadPoolExecutor.java:630)
	at java.base/java.lang.Thread.run(Thread.java:832)
]]>
    </error>
  </testcase> <!-- validateTitle -->
</testsuite> <!-- Salesforce.E2E_AutomationTest.ValidateTitle -->
