<?xml version="1.0" encoding="UTF-8"?>
<!-- Generated by org.testng.reporters.JUnitXMLReporter -->
<testsuite hostname="DESKTOP-OOA8I55" failures="1" tests="1" name="Validating title in the page" time="14.047" errors="0" timestamp="30 Jun 2021 18:57:27 GMT">
  <testcase classname="Salesforce.E2E_AutomationTest.ValidateTitle" name="validateTitle" time="4.656">
    <failure type="java.lang.AssertionError" message="expected [Get back to growth with the world’s #1 CRM, powered by Customer 360] but found [Get back to growth with the world’s #1 CRM, powered by Customer 360.]">
      <![CDATA[java.lang.AssertionError: expected [Get back to growth with the world’s #1 CRM, powered by Customer 360] but found [Get back to growth with the world’s #1 CRM, powered by Customer 360.]
	at Salesforce.E2E_AutomationTest.ValidateTitle.validateTitle(ValidateTitle.java:45)
	at java.base/java.util.concurrent.FutureTask.run(FutureTask.java:264)
	at java.base/java.util.concurrent.ThreadPoolExecutor.runWorker(ThreadPoolExecutor.java:1130)
	at java.base/java.util.concurrent.ThreadPoolExecutor$Worker.run(ThreadPoolExecutor.java:630)
	at java.base/java.lang.Thread.run(Thread.java:832)
... Removed 21 stack frames]]>
    </failure>
  </testcase> <!-- validateTitle -->
</testsuite> <!-- Validating title in the page -->
